Workbook

Sheet Roads
A1: check_id | B1: city | C1: road_name | D1: from_cross_street | E1: to_cross_street | F1: osm_way_id | G1: our_speed_mph | H1: our_speed_source | I1: cart_legal_per_map | J1: street_view_link | K1: map_link | L1: posted_speed_seen_mph | M1: sign_location_note | N1: imagery_date | O1: confidence | P1: status | Q1: checker_initials | R1: notes | S1: our_gis_survey_mph | T1: gis_survey_source | U1: source_link | V1: agree_YN | W1: resolved_mph | X1: why_in_batch | Y1: routes_using | Z1: length_m | AA1: region | AB1: gcm_ref
A2: SD-B2-001 | B2: San Diego area | C2: 7th Street | D2: Palm Avenue | E2: Silver Strand Boulevard | F2: 1347742299 | H2: inferred | I2: no | J2: https://www.google.com/maps/@?api=1&map_action=pano&viewpoint=32.584135,-117.118030&heading=180 | K2: https://www.google.com/maps/search/?api=1&query=32.584135,-117.118030 | P2: pending | V2: =IF(OR(L2="",S2=""),"",IF(VALUE(L2)=VALUE(S2),"Y","N")) | W2: =IF(V2="Y",S2,"") | X2: RED ISLAND: 77 m of 7th Street at no limit between 25 mph on both sides (gap); is the posted limit really higher here? | Z2: 77 | AA2: sd | AB2: sd|32.58414,-117.11803
A3: SD-B2-002 | B3: San Diego area | C3: West Plaza Boulevard | D3: (see map link) | E3: Coolidge Avenue | F3: 1346159098 | H3: inferred | I3: no | J3: https://www.google.com/maps/@?api=1&map_action=pano&viewpoint=32.673290,-117.109105&heading=71 | K3: https://www.google.com/maps/search/?api=1&query=32.673290,-117.109105 | P3: pending | V3: =IF(OR(L3="",S3=""),"",IF(VALUE(L3)=VALUE(S3),"Y","N")) | W3: =IF(V3="Y",S3,"") | X3: RED ISLAND: 271 m of West Plaza Boulevard at no limit between 25 mph on both sides (gap); is the posted limit really higher here? | Z3: 271 | AA3: sd | AB3: sd|32.67329,-117.10910
A4: SD-B2-003 | B4: San Diego area | C4: Ocean Boulevard | D4: Alameda Boulevard | E4: R.H. Dana Place | F4: 5959682 | H4: inferred | I4: no | J4: https://www.google.com/maps/@?api=1&map_action=pano&viewpoint=32.682930,-117.182105&heading=122 | K4: https://www.google.com/maps/search/?api=1&query=32.682930,-117.182105 | P4: pending | V4: =IF(OR(L4="",S4=""),"",IF(VALUE(L4)=VALUE(S4),"Y","N")) | W4: =IF(V4="Y",S4,"") | X4: RED ISLAND: 465 m of Ocean Boulevard at no limit between 25 mph on both sides (gap); is the posted limit really higher here? | Z4: 465 | AA4: sd | AB4: sd|32.68293,-117.18211
A5: SD-B2-004 | B5: San Diego area | C5: Osborn Street | D5: Division Street | E5: East 1st Street | H5: inferred | I5: no | J5: https://www.google.com/maps/@?api=1&map_action=pano&viewpoint=32.682925,-117.109700&heading=161 | K5: https://www.google.com/maps/search/?api=1&query=32.682925,-117.109700 | P5: pending | V5: =IF(OR(L5="",S5=""),"",IF(VALUE(L5)=VALUE(S5),"Y","N")) | W5: =IF(V5="Y",S5,"") | X5: RED ISLAND: 249 m of Osborn Street at no limit between 25 mph on both sides (gap); is the posted limit really higher here? | Z5: 249 | AA5: sd | AB5: sd|32.68292,-117.10970
A6: SD-B2-005 | B6: San Diego area | C6: West 18th Street | D6: (see map link) | E6: West 19th Street | F6: 136517093 | H6: inferred | I6: no | J6: https://www.google.com/maps/@?api=1&map_action=pano&viewpoint=32.665370,-117.110165&heading=251 | K6: https://www.google.com/maps/search/?api=1&query=32.665370,-117.110165 | P6: pending | V6: =IF(OR(L6="",S6=""),"",IF(VALUE(L6)=VALUE(S6),"Y","N")) | W6: =IF(V6="Y",S6,"") | X6: RED ISLAND: 303 m of West 18th Street at no limit between 25 mph on both sides (gap); is the posted limit really higher here? | Z6: 303 | AA6: sd | AB6: sd|32.66537,-117.11016
A7: SD-B2-006 | B7: San Diego area | C7: Civic Center Drive | D7: East Harbor Drive | E7: Cleveland Avenue | F7: 151692017 | H7: inferred | I7: no | J7: https://www.google.com/maps/@?api=1&map_action=pano&viewpoint=32.669305,-117.113145&heading=253 | K7: https://www.google.com/maps/search/?api=1&query=32.669305,-117.113145 | P7: pending | V7: =IF(OR(L7="",S7=""),"",IF(VALUE(L7)=VALUE(S7),"Y","N")) | W7: =IF(V7="Y",S7,"") | X7: RED ISLAND: 106 m of Civic Center Drive at no limit between 25/30 mph on both sides (gap); is the posted limit really higher here? | Z7: 106 | AA7: sd | AB7: sd|32.66931,-117.11315
A8: SD-B2-007 | B8: San Diego area | C8: 1st Street | D8: Orange Avenue | E8: D Avenue | F8: 1346399905 | H8: inferred | I8: no | J8: https://www.google.com/maps/@?api=1&map_action=pano&viewpoint=32.698100,-117.170775&heading=117 | K8: https://www.google.com/maps/search/?api=1&query=32.698100,-117.170775 | P8: pending | V8: =IF(OR(L8="",S8=""),"",IF(VALUE(L8)=VALUE(S8),"Y","N")) | W8: =IF(V8="Y",S8,"") | X8: RED ISLAND: 588 m of 1st Street at no limit between 25 mph on both sides (gap); is the posted limit really higher here? | Z8: 588 | AA8: sd | AB8: sd|32.69810,-117.17077
A9: SD-B2-008 | B9: San Diego area | C9: Boston Avenue | D9: South 28th Street | E9: South 29th Street | F9: 1341614180 | H9: inferred | I9: no | J9: https://www.google.com/maps/@?api=1&map_action=pano&viewpoint=32.693840,-117.132485&heading=90 | K9: https://www.google.com/maps/search/?api=1&query=32.693840,-117.132485 | P9: pending | V9: =IF(OR(L9="",S9=""),"",IF(VALUE(L9)=VALUE(S9),"Y","N")) | W9: =IF(V9="Y",S9,"") | X9: RED ISLAND: 201 m of Boston Avenue at no limit between 25 mph on both sides (gap); is the posted limit really higher here? | Z9: 201 | AA9: sd | AB9: sd|32.69384,-117.13249
A10: SD-B2-009 | B10: San Diego area | C10: 1st Street | D10: (see map link) | E10: I Avenue | F10: 1526415634 | H10: inferred | I10: no | J10: https://www.google.com/maps/@?api=1&map_action=pano&viewpoint=32.700540,-117.176560&heading=116 | K10: https://www.google.com/maps/search/?api=1&query=32.700540,-117.176560 | P10: pending | V10: =IF(OR(L10="",S10=""),"",IF(VALUE(L10)=VALUE(S10),"Y","N")) | W10: =IF(V10="Y",S10,"") | X10: RED ISLAND: 692 m of 1st Street at no limit between 25 mph on both sides (gap); is the posted limit really higher here? | Z10: 692 | AA10: sd | AB10: sd|32.70054,-117.17656
A11: SD-B2-010 | B11: San Diego area | C11: Kettner Boulevard | D11: (see map link) | E11: Market Place | F11: 1098930355 | G11: 40 | H11: tag | I11: no | J11: https://www.google.com/maps/@?api=1&map_action=pano&viewpoint=32.710760,-117.169210&heading=180 | K11: https://www.google.com/maps/search/?api=1&query=32.710760,-117.169210 | P11: pending | V11: =IF(OR(L11="",S11=""),"",IF(VALUE(L11)=VALUE(S11),"Y","N")) | W11: =IF(V11="Y",S11,"") | X11: RED ISLAND: 461 m of Kettner Boulevard at 40 mph between 15/25 mph on both sides (single); is the posted limit really higher here? | Z11: 461 | AA11: sd | AB11: sd|32.71076,-117.16921
A12: SD-B2-011 | B12: San Diego area | C12: North 19th Street | D12: East Island Avenue | E12: Market Street | H12: inferred | I12: no | J12: https://www.google.com/maps/@?api=1&map_action=pano&viewpoint=32.711000,-117.146710&heading=0 | K12: https://www.google.com/maps/search/?api=1&query=32.711000,-117.146710 | P12: pending | V12: =IF(OR(L12="",S12=""),"",IF(VALUE(L12)=VALUE(S12),"Y","N")) | W12: =IF(V12="Y",S12,"") | X12: RED ISLAND: 299 m of North 19th Street at no limit between 25 mph on both sides (gap); is the posted limit really higher here? | Z12: 299 | AA12: sd | AB12: sd|32.71100,-117.14671
A13: SD-B2-012 | B13: San Diego area | C13: Lincoln Avenue | D13: (see map link) | E13: (see map link) | F13: 25298033 | H13: inferred | I13: no | J13: https://www.google.com/maps/@?api=1&map_action=pano&viewpoint=32.750370,-117.123270&heading=90 | K13: https://www.google.com/maps/search/?api=1&query=32.750370,-117.123270 | P13: pending | V13: =IF(OR(L13="",S13=""),"",IF(VALUE(L13)=VALUE(S13),"Y","N")) | W13: =IF(V13="Y",S13,"") | X13: RED ISLAND: 81 m of Lincoln Avenue at no limit between 25/30 mph on both sides (gap); is the posted limit really higher here? | Z13: 81 | AA13: sd | AB13: sd|32.75037,-117.12327
A14: SD-B2-013 | B14: San Diego area | C14: J Street | D14: (see map link) | E14: North 19th Street | F14: 25518446 | H14: inferred | I14: no | J14: https://www.google.com/maps/@?api=1&map_action=pano&viewpoint=32.709415,-117.147590&heading=89 | K14: https://www.google.com/maps/search/?api=1&query=32.709415,-117.147590 | P14: pending | V14: =IF(OR(L14="",S14=""),"",IF(VALUE(L14)=VALUE(S14),"Y","N")) | W14: =IF(V14="Y",S14,"") | X14: RED ISLAND: 124 m of J Street at no limit between 25 mph on both sides (gap); is the posted limit really higher here? | Z14: 124 | AA14: sd | AB14: sd|32.70941,-117.14759
A15: SD-B2-014 | B15: San Diego area | C15: Mission Avenue | D15: Shirley Ann Place | E15: Madison Avenue | F15: 1415679779 | H15: inferred | I15: no | J15: https://www.google.com/maps/@?api=1&map_action=pano&viewpoint=32.761375,-117.139355&heading=28 | K15: https://www.google.com/maps/search/?api=1&query=32.761375,-117.139355 | P15: pending | V15: =IF(OR(L15="",S15=""),"",IF(VALUE(L15)=VALUE(S15),"Y","N")) | W15: =IF(V15="Y",S15,"") | X15: RED ISLAND: 138 m of Mission Avenue at no limit between 25 mph on both sides (gap); is the posted limit really higher here? | Z15: 138 | AA15: sd | AB15: sd|32.76138,-117.13935
A16: SD-B2-015 | B16: San Diego area | C16: K Street | D16: 4th Avenue | E16: 5th Avenue | H16: inferred | I16: no | J16: https://www.google.com/maps/@?api=1&map_action=pano&viewpoint=32.708320,-117.160580&heading=90 | K16: https://www.google.com/maps/search/?api=1&query=32.708320,-117.160580 | P16: pending | V16: =IF(OR(L16="",S16=""),"",IF(VALUE(L16)=VALUE(S16),"Y","N")) | W16: =IF(V16="Y",S16,"") | X16: RED ISLAND: 88 m of K Street at no limit between 25 mph on both sides (gap); is the posted limit really higher here? | Z16: 88 | AA16: sd | AB16: sd|32.70832,-117.16058
A17: SD-B2-016 | B17: San Diego area | C17: Boundary Street | D17: (see map link) | E17: University Avenue | H17: inferred | I17: no | J17: https://www.google.com/maps/@?api=1&map_action=pano&viewpoint=32.747635,-117.122910&heading=178 | K17: https://www.google.com/maps/search/?api=1&query=32.747635,-117.122910 | P17: pending | V17: =IF(OR(L17="",S17=""),"",IF(VALUE(L17)=VALUE(S17),"Y","N")) | W17: =IF(V17="Y",S17,"") | X17: RED ISLAND: 121 m of Boundary Street at no limit between 25 mph on both sides (gap); is the posted limit really higher here? | Z17: 121 | AA17: sd | AB17: sd|32.74764,-117.12291
A18: SD-B2-017 | B18: San Diego area | C18: Pacific Highway | D18: Waterfront Place | E18: Midway Place | F18: 436287704 | H18: inferred | I18: no | J18: https://www.google.com/maps/@?api=1&map_action=pano&viewpoint=32.714295,-117.171160&heading=178 | K18: https://www.google.com/maps/search/?api=1&query=32.714295,-117.171160 | P18: pending | V18: =IF(OR(L18="",S18=""),"",IF(VALUE(L18)=VALUE(S18),"Y","N")) | W18: =IF(V18="Y",S18,"") | X18: RED ISLAND: 475 m of Pacific Highway at no limit between 25/35 mph on both sides (gap); is the posted limit really higher here? | Z18: 475 | AA18: sd | AB18: sd|32.71429,-117.17116
A19: SD-B2-018 | B19: San Diego area | C19: Park Boulevard | D19: East Broadway | E19: East B Street | F19: 621450949 | H19: inferred | I19: no | J19: https://www.google.com/maps/@?api=1&map_action=pano&viewpoint=32.716890,-117.153700&heading=34 | K19: https://www.google.com/maps/search/?api=1&query=32.716890,-117.153700 | P19: pending | V19: =IF(OR(L19="",S19=""),"",IF(VALUE(L19)=VALUE(S19),"Y","N")) | W19: =IF(V19="Y",S19,"") | X19: RED ISLAND: 701 m of Park Boulevard at no limit between 25 mph on both sides (gap); is the posted limit really higher here? | Z19: 701 | AA19: sd | AB19: sd|32.71689,-117.15370
A20: SD-B2-019 | B20: San Diego area | C20: Upas Street | D20: 30th Street | E20: 30th Street | H20: inferred | I20: no | J20: https://www.google.com/maps/@?api=1&map_action=pano&viewpoint=32.741095,-117.129500&heading=96 | K20: https://www.google.com/maps/search/?api=1&query=32.741095,-117.129500 | P20: pending | V20: =IF(OR(L20="",S20=""),"",IF(VALUE(L20)=VALUE(S20),"Y","N")) | W20: =IF(V20="Y",S20,"") | X20: RED ISLAND: 94 m of Upas Street at no limit between 25 mph on both sides (gap); is the posted limit really higher here? | Z20: 94 | AA20: sd | AB20: sd|32.74110,-117.12950
A21: SD-B2-020 | B21: San Diego area | C21: Morena Boulevard | D21: Napa Street | E21: West Morena Boulevard | F21: 234852472 | H21: inferred | I21: no | J21: https://www.google.com/maps/@?api=1&map_action=pano&viewpoint=32.765010,-117.198190&heading=158 | K21: https://www.google.com/maps/search/?api=1&query=32.765010,-117.198190 | P21: pending | V21: =IF(OR(L21="",S21=""),"",IF(VALUE(L21)=VALUE(S21),"Y","N")) | W21: =IF(V21="Y",S21,"") | X21: RED ISLAND: 572 m of Morena Boulevard at 40 mph between 30/35 mph on both sides (single); is the posted limit really higher here? | Z21: 572 | AA21: sd | AB21: sd|32.76501,-117.19819
A22: SD-B2-021 | B22: San Diego area | C22: Morena Boulevard | D22: Napa Street | E22: West Morena Boulevard | F22: 1071947302 | H22: inferred | I22: no | J22: https://www.google.com/maps/@?api=1&map_action=pano&viewpoint=32.766685,-117.198810&heading=338 | K22: https://www.google.com/maps/search/?api=1&query=32.766685,-117.198810 | P22: pending | V22: =IF(OR(L22="",S22=""),"",IF(VALUE(L22)=VALUE(S22),"Y","N")) | W22: =IF(V22="Y",S22,"") | X22: RED ISLAND: 162 m of Morena Boulevard at no limit between 30/35 mph on both sides (gap); is the posted limit really higher here? | Z22: 162 | AA22: sd | AB22: sd|32.76668,-117.19881
A23: SD-B2-022 | B23: San Diego area | C23: Camino del Este | D23: Camino del Rio North | E23: Station Village Lane | F23: 159135343 | H23: inferred | I23: no | J23: https://www.google.com/maps/@?api=1&map_action=pano&viewpoint=32.772575,-117.144730&heading=345 | K23: https://www.google.com/maps/search/?api=1&query=32.772575,-117.144730 | P23: pending | V23: =IF(OR(L23="",S23=""),"",IF(VALUE(L23)=VALUE(S23),"Y","N")) | W23: =IF(V23="Y",S23,"") | X23: RED ISLAND: 742 m of Camino del Este at no limit between 25 mph on both sides (gap); is the posted limit really higher here? | Z23: 742 | AA23: sd | AB23: sd|32.77258,-117.14473
A24: SD-B2-023 | B24: San Diego area | C24: Wabash Avenue | D24: (see map link) | E24: University Avenue | F24: 182002455 | H24: inferred | I24: no | J24: https://www.google.com/maps/@?api=1&map_action=pano&viewpoint=32.748870,-117.120700&heading=344 | K24: https://www.google.com/maps/search/?api=1&query=32.748870,-117.120700 | P24: pending | V24: =IF(OR(L24="",S24=""),"",IF(VALUE(L24)=VALUE(S24),"Y","N")) | W24: =IF(V24="Y",S24,"") | X24: RED ISLAND: 49 m of Wabash Avenue at no limit between 25 mph on both sides (gap); is the posted limit really higher here? | Z24: 49 | AA24: sd | AB24: sd|32.74887,-117.12070
A25: SD-B2-024 | B25: San Diego area | C25: Mission Valley Road | D25: Mission Center Road | E25: Metropolitan Drive | F25: 641733672 | H25: inferred | I25: no | J25: https://www.google.com/maps/@?api=1&map_action=pano&viewpoint=32.777920,-117.156060&heading=276 | K25: https://www.google.com/maps/search/?api=1&query=32.777920,-117.156060 | P25: pending | V25: =IF(OR(L25="",S25=""),"",IF(VALUE(L25)=VALUE(S25),"Y","N")) | W25: =IF(V25="Y",S25,"") | X25: RED ISLAND: 461 m of Mission Valley Road at no limit between 25/35 mph on both sides (gap); is the posted limit really higher here? | Z25: 461 | AA25: sd | AB25: sd|32.77792,-117.15606
A26: SD-B2-025 | B26: San Diego area | C26: Fort Stockton Drive | D26: Sunset Boulevard | E26: Stephens Street | F26: 225763786 | H26: inferred | I26: no | J26: https://www.google.com/maps/@?api=1&map_action=pano&viewpoint=32.750880,-117.179240&heading=138 | K26: https://www.google.com/maps/search/?api=1&query=32.750880,-117.179240 | P26: pending | V26: =IF(OR(L26="",S26=""),"",IF(VALUE(L26)=VALUE(S26),"Y","N")) | W26: =IF(V26="Y",S26,"") | X26: RED ISLAND: 123 m of Fort Stockton Drive at no limit between 25 mph on both sides (gap); is the posted limit really higher here? | Z26: 123 | AA26: sd | AB26: sd|32.75088,-117.17924
A27: SD-B2-026 | B27: San Diego area | C27: Market Street | D27: (see map link) | E27: 24th Street | F27: 436305535 | H27: inferred | I27: no | J27: https://www.google.com/maps/@?api=1&map_action=pano&viewpoint=32.711540,-117.144445&heading=90 | K27: https://www.google.com/maps/search/?api=1&query=32.711540,-117.144445 | P27: pending | V27: =IF(OR(L27="",S27=""),"",IF(VALUE(L27)=VALUE(S27),"Y","N")) | W27: =IF(V27="Y",S27,"") | X27: RED ISLAND: 283 m of Market Street at no limit between 25/30 mph on both sides (gap); is the posted limit really higher here? | Z27: 283 | AA27: sd | AB27: sd|32.71154,-117.14445
A28: SD-B2-027 | B28: San Diego area | C28: 6th Avenue | D28: Upas Street | E28: Balboa Drive | F28: 436407058 | H28: inferred | I28: no | J28: https://www.google.com/maps/@?api=1&map_action=pano&viewpoint=32.740965,-117.159425&heading=350 | K28: https://www.google.com/maps/search/?api=1&query=32.740965,-117.159425 | P28: pending | V28: =IF(OR(L28="",S28=""),"",IF(VALUE(L28)=VALUE(S28),"Y","N")) | W28: =IF(V28="Y",S28,"") | X28: RED ISLAND: 25 m of 6th Avenue at no limit between 30 mph on both sides (gap); is the posted limit really higher here? | Z28: 25 | AA28: sd | AB28: sd|32.74097,-117.15942
A29: SD-B2-028 | B29: San Diego area | C29: Lincoln Avenue | D29: 32nd Street | E29: Boundary Street | F29: 159273817 | H29: inferred | I29: no | J29: https://www.google.com/maps/@?api=1&map_action=pano&viewpoint=32.750360,-117.124395&heading=90 | K29: https://www.google.com/maps/search/?api=1&query=32.750360,-117.124395 | P29: pending | V29: =IF(OR(L29="",S29=""),"",IF(VALUE(L29)=VALUE(S29),"Y","N")) | W29: =IF(V29="Y",S29,"") | X29: RED ISLAND: 145 m of Lincoln Avenue at no limit between 25 mph on both sides (gap); is the posted limit really higher here? | Z29: 145 | AA29: sd | AB29: sd|32.75036,-117.12439
A30: SD-B2-029 | B30: San Diego area | C30: East C Street | D30: North 16th Street | E30: North 17th Street | F30: 1026612446 | H30: inferred | I30: no | J30: https://www.google.com/maps/@?api=1&map_action=pano&viewpoint=32.716805,-117.149005&heading=89 | K30: https://www.google.com/maps/search/?api=1&query=32.716805,-117.149005 | P30: pending | V30: =IF(OR(L30="",S30=""),"",IF(VALUE(L30)=VALUE(S30),"Y","N")) | W30: =IF(V30="Y",S30,"") | X30: RED ISLAND: 84 m of East C Street at no limit between 25 mph on both sides (gap); is the posted limit really higher here? | Z30: 84 | AA30: sd | AB30: sd|32.71681,-117.14901
A31: SD-B2-030 | B31: San Diego area | C31: Wightman Street | D31: Swift Avenue | E31: (see map link) | H31: inferred | I31: no | J31: https://www.google.com/maps/@?api=1&map_action=pano&viewpoint=32.747905,-117.118845&heading=89 | K31: https://www.google.com/maps/search/?api=1&query=32.747905,-117.118845 | P31: pending | V31: =IF(OR(L31="",S31=""),"",IF(VALUE(L31)=VALUE(S31),"Y","N")) | W31: =IF(V31="Y",S31,"") | X31: RED ISLAND: 124 m of Wightman Street at no limit between 25 mph on both sides (gap); is the posted limit really higher here? | Z31: 124 | AA31: sd | AB31: sd|32.74791,-117.11884
A32: SD-B2-031 | B32: San Diego area | C32: India Street | D32: Chalmers Street | E32: San Diego Avenue | F32: 1119813420 | H32: inferred | I32: no | J32: https://www.google.com/maps/@?api=1&map_action=pano&viewpoint=32.741720,-117.179850&heading=327 | K32: https://www.google.com/maps/search/?api=1&query=32.741720,-117.179850 | P32: pending | V32: =IF(OR(L32="",S32=""),"",IF(VALUE(L32)=VALUE(S32),"Y","N")) | W32: =IF(V32="Y",S32,"") | X32: RED ISLAND: 36 m of India Street at no limit between 25/35 mph on both sides (gap); is the posted limit really higher here? | Z32: 36 | AA32: sd | AB32: sd|32.74172,-117.17985
A33: SD-B2-032 | B33: San Diego area | C33: North 16th Street | D33: East B Street | E33: (see map link) | F33: 1242731129 | H33: inferred | I33: no | J33: https://www.google.com/maps/@?api=1&map_action=pano&viewpoint=32.717350,-117.149500&heading=358 | K33: https://www.google.com/maps/search/?api=1&query=32.717350,-117.149500 | P33: pending | V33: =IF(OR(L33="",S33=""),"",IF(VALUE(L33)=VALUE(S33),"Y","N")) | W33: =IF(V33="Y",S33,"") | X33: RED ISLAND: 107 m of North 16th Street at no limit between 25 mph on both sides (gap); is the posted limit really higher here? | Z33: 107 | AA33: sd | AB33: sd|32.71735,-117.14950
A34: SD-B2-033 | B34: San Diego area | C34: Clairemont Drive | D34: (see map link) | E34: Iroquois Avenue | F34: 436423866 | H34: inferred | I34: no | J34: https://www.google.com/maps/@?api=1&map_action=pano&viewpoint=32.795800,-117.193380&heading=11 | K34: https://www.google.com/maps/search/?api=1&query=32.795800,-117.193380 | P34: pending | V34: =IF(OR(L34="",S34=""),"",IF(VALUE(L34)=VALUE(S34),"Y","N")) | W34: =IF(V34="Y",S34,"") | X34: RED ISLAND: 347 m of Clairemont Drive at no limit between 35 mph on both sides (gap); is the posted limit really higher here? | Z34: 347 | AA34: sd | AB34: sd|32.79580,-117.19338
A35: SD-B2-034 | B35: San Diego area | C35: Sandrock Road | D35: Hammond Drive | E35: Gramercy Drive | F35: 907920660 | H35: inferred | I35: no | J35: https://www.google.com/maps/@?api=1&map_action=pano&viewpoint=32.803715,-117.139695&heading=147 | K35: https://www.google.com/maps/search/?api=1&query=32.803715,-117.139695 | P35: pending | V35: =IF(OR(L35="",S35=""),"",IF(VALUE(L35)=VALUE(S35),"Y","N")) | W35: =IF(V35="Y",S35,"") | X35: RED ISLAND: 543 m of Sandrock Road at no limit between 25/35 mph on both sides (gap); is the posted limit really higher here? | Z35: 543 | AA35: sd | AB35: sd|32.80371,-117.13969
A36: SD-B2-035 | B36: San Diego area | C36: Camino del Sur | D36: Park Village Road | E36: Park Village Road | F36: 225758759 | H36: inferred | I36: no | J36: https://www.google.com/maps/@?api=1&map_action=pano&viewpoint=32.940920,-117.151865&heading=15 | K36: https://www.google.com/maps/search/?api=1&query=32.940920,-117.151865 | P36: pending | V36: =IF(OR(L36="",S36=""),"",IF(VALUE(L36)=VALUE(S36),"Y","N")) | W36: =IF(V36="Y",S36,"") | X36: RED ISLAND: 202 m of Camino del Sur at no limit between 25 mph on both sides (gap); is the posted limit really higher here? | Z36: 202 | AA36: sd | AB36: sd|32.94092,-117.15187
A37: SD-B2-036 | B37: San Diego area | C37: Rancho Santa Fe Farms Road | D37: Carmel Valley Road | E37: (see map link) | F37: 178595486 | G37: 40 | H37: tag | I37: no | J37: https://www.google.com/maps/@?api=1&map_action=pano&viewpoint=32.968410,-117.178470&heading=348 | K37: https://www.google.com/maps/search/?api=1&query=32.968410,-117.178470 | P37: pending | V37: =IF(OR(L37="",S37=""),"",IF(VALUE(L37)=VALUE(S37),"Y","N")) | W37: =IF(V37="Y",S37,"") | X37: RED ISLAND: 52 m of Rancho Santa Fe Farms Road at 40 mph between 25/35 mph on both sides (single); is the posted limit really higher here? | Z37: 52 | AA37: sd | AB37: sd|32.96841,-117.17847
A38: SD-B2-037 | B38: San Diego area | C38: Point Loma Avenue | D38: Sunset Cliffs Boulevard | E38: Ebers Street | H38: inferred | I38: no | J38: https://www.google.com/maps/@?api=1&map_action=pano&viewpoint=32.734810,-117.252415&heading=125 | K38: https://www.google.com/maps/search/?api=1&query=32.734810,-117.252415 | P38: pending | V38: =IF(OR(L38="",S38=""),"",IF(VALUE(L38)=VALUE(S38),"Y","N")) | W38: =IF(V38="Y",S38,"") | X38: RED ISLAND: 400 m of Point Loma Avenue at no limit between 25 mph on both sides (gap); is the posted limit really higher here? | Z38: 400 | AA38: sd | AB38: sd|32.73481,-117.25241
A39: SD-B2-038 | B39: San Diego area | C39: Nimitz Boulevard | D39: Chatsworth Boulevard | E39: Poe Street | F39: 1518707819 | H39: inferred | I39: no | J39: https://www.google.com/maps/@?api=1&map_action=pano&viewpoint=32.736975,-117.230535&heading=163 | K39: https://www.google.com/maps/search/?api=1&query=32.736975,-117.230535 | P39: pending | V39: =IF(OR(L39="",S39=""),"",IF(VALUE(L39)=VALUE(S39),"Y","N")) | W39: =IF(V39="Y",S39,"") | X39: RED ISLAND: 87 m of Nimitz Boulevard at no limit between 35 mph on both sides (gap); is the posted limit really higher here? | Z39: 87 | AA39: sd | AB39: sd|32.73698,-117.23054
A40: SD-B2-039 | B40: San Diego area | C40: Nimitz Boulevard | D40: Atascadero Drive | E40: Bernice Drive | H40: inferred | I40: no | J40: https://www.google.com/maps/@?api=1&map_action=pano&viewpoint=32.738925,-117.231335&heading=159 | K40: https://www.google.com/maps/search/?api=1&query=32.738925,-117.231335 | P40: pending | V40: =IF(OR(L40="",S40=""),"",IF(VALUE(L40)=VALUE(S40),"Y","N")) | W40: =IF(V40="Y",S40,"") | X40: RED ISLAND: 87 m of Nimitz Boulevard at no limit between 25/35 mph on both sides (gap); is the posted limit really higher here? | Z40: 87 | AA40: sd | AB40: sd|32.73892,-117.23134
...

Sheet How to check
A1: Street View batch 2: 1,000 stretches, San Diego first. Rows are in priority order within each region: RED ISLAND rows first (a short piece of a road shows as not allowed while the same road is 35 mph or less on both sides; tell us the posted limit on that piece), then roads whose limit we only guessed or took from one unverified source, right at the 25 mph (golf cart) or 35 mph (LSV) line.
A2: Same as batch 1: fill only the blue columns (posted_speed_seen_mph … notes). If no speed sign is visible on the stretch, set status to "can't tell" and move on (5 minute cap per row). Row order is priority order, so stopping partway is fine.
A4: # Golf Cart Maps — Street View speed-limit checker guide
A6: Purpose: confirm the POSTED speed limit on each road in the sheet using Google Maps Street View. The answer decides whether the road is legal for golf carts (posted 25 mph or less) and LSVs (posted 35 mph or less). A wrong number can send someone onto an illegal road, so record only what you actually see on a sign. Never guess.
A8: Time budget: about 2-3 minutes per road. If a road takes more than 5 minutes, stop, set status to "can't tell", write what you saw in notes, and move on.
A10: ## Before you start
A11: 1. Use a computer (laptop/desktop) with Chrome, Firefox, Safari or Edge. A phone works but is much slower.
A12: 2. Open the Google Sheet. Go to the "Roads" tab.
A13: 3. Find the first row where status = "pending" and checker_initials is empty. Type your initials in checker_initials right away so nobody else picks the same row.
A14: 4. Each row is one road segment: road_name, between from_cross_street and to_cross_street, in the given city. "(nearby)" means the cross street is near but not touching that end; "(next block)" means both ends meet the same street; "(see map)" means use map_link to see where it is.
A16: ## Step-by-step for each row
A17: 1. Click the street_view_link in that row. It opens Google Maps in Street View at a point in the middle of the segment, facing along the road.
... A65: - For two-source agreement (the plan requires two agreeing sources before a popular-route segment shows as verified), the sheet gets second_checker_initials and second_posted_speed_mph columns. A different person re-checks a row without looking at the first answer; the row is verified only when both match. The Summary tab tracks done, mismatches against our map, and percent complete.

Sheet Summary
A1: metric | B1: value
A2: total roads | B2: =COUNTA(Roads!A2:A1001)
A3: done | B3: =COUNTIF(Roads!P2:P1001,"done")
A4: can't tell | B4: =COUNTIF(Roads!P2:P1001,"can't tell")
A5: pending | B5: =COUNTIF(Roads!P2:P1001,"pending")
A6: percent done | B6: =IF(B2=0,0,(B3+B4)/B2)
A7: compared (sign read and we have a GIS/survey value) | B7: =COUNTIF(Roads!V2:V1001,"Y")+COUNTIF(Roads!V2:V1001,"N")
A8: agreed (Y) | B8: =COUNTIF(Roads!V2:V1001,"Y")
A9: disagreed (N) | B9: =COUNTIF(Roads!V2:V1001,"N")
A10: % agreed | B10: =IF(B7=0,"",B8/B7)
A11: mismatched vs our map (done rows) | B11: =SUMPRODUCT((Roads!P2:P1001="done")*(Roads!L2:L1001<>"")*(Roads!L2:L1001<>Roads!G2:G1001))
A12: red island rows | B12: =COUNTIF(Roads!X2:X1001,"RED ISLAND*")
