Workbook

Sheet Roads
A1: check_id | B1: city | C1: road_name | D1: from_cross_street | E1: to_cross_street | F1: osm_way_id | G1: our_speed_mph | H1: our_speed_source | I1: cart_legal_per_map | J1: street_view_link | K1: map_link | L1: posted_speed_seen_mph | M1: sign_location_note | N1: imagery_date | O1: confidence | P1: status | Q1: checker_initials | R1: notes | S1: our_gis_survey_mph | T1: gis_survey_source | U1: source_link | V1: agree_YN | W1: resolved_mph | X1: why_in_batch | Y1: routes_using | Z1: length_m
A2: CBD-B1-001 | B2: Carlsbad | C2: Carlsbad Boulevard | D2: North Coast Highway | E2: Avenida Encinas | F2: 436431496 | G2: 50 | H2: city/county | I2: no | J2: https://www.google.com/maps/@?api=1&map_action=pano&viewpoint=33.089322,-117.312881&heading=343 | K2: https://www.google.com/maps/search/?api=1&query=33.089322,-117.312881 | P2: pending | S2: 50 | T2: Carlsbad Blvd (Island Way - south city limit (Batiquitos Lagoon to Leucadia)) | U2: https://ecode360.com/44006773 | V2: =IF(OR(L2="",S2=""),"",IF(VALUE(L2)=VALUE(S2),"Y","N")) | W2: =IF(V2="Y",S2,"") | X2: sources disagree: map uses the official 50 mph (OSM/imagery: osm 30) | Y2: 1 | Z2: 268
A3: CBD-B1-002 | B3: Carlsbad | C3: Carlsbad Boulevard | D3: North Coast Highway | E3: Avenida Encinas | F3: 436431495 | G3: 50 | H3: city/county | I3: no | J3: https://www.google.com/maps/@?api=1&map_action=pano&viewpoint=33.091718,-117.313771&heading=343 | K3: https://www.google.com/maps/search/?api=1&query=33.091718,-117.313771 | P3: pending | S3: 50 | T3: Carlsbad Blvd (Island Way - south city limit (Batiquitos Lagoon to Leucadia)) | U3: https://ecode360.com/44006773 | V3: =IF(OR(L3="",S3=""),"",IF(VALUE(L3)=VALUE(S3),"Y","N")) | W3: =IF(V3="Y",S3,"") | X3: sources disagree: map uses the official 50 mph (OSM/imagery: osm 30) | Y3: 1 | Z3: 193
A4: CBD-B1-003 | B4: Carlsbad | C4: Carlsbad Boulevard | D4: Ponto Road | E4: Avenida Encinas | F4: 436431493 | G4: 50 | H4: city/county | I4: no | J4: https://www.google.com/maps/@?api=1&map_action=pano&viewpoint=33.091805,-117.314255&heading=161 | K4: https://www.google.com/maps/search/?api=1&query=33.091805,-117.314255 | P4: pending | S4: 50 | T4: Carlsbad Blvd (Island Way - south city limit (Batiquitos Lagoon to Leucadia)) | U4: https://ecode360.com/44006773 | V4: =IF(OR(L4="",S4=""),"",IF(VALUE(L4)=VALUE(S4),"Y","N")) | W4: =IF(V4="Y",S4,"") | X4: one official source; most-used arterial | Y4: 1 | Z4: 154
A5: CBD-B1-004 | B5: Carlsbad | C5: Carlsbad Boulevard | D5: Avenida Encinas | E5: Ponto Road | F5: 908227120 | G5: 50 | H5: city/county | I5: no | J5: https://www.google.com/maps/@?api=1&map_action=pano&viewpoint=33.093700,-117.314556&heading=340 | K5: https://www.google.com/maps/search/?api=1&query=33.093700,-117.314556 | P5: pending | S5: 50 | T5: Carlsbad Blvd (Island Way - south city limit (Batiquitos Lagoon to Leucadia)) | U5: https://ecode360.com/44006773 | V5: =IF(OR(L5="",S5=""),"",IF(VALUE(L5)=VALUE(S5),"Y","N")) | W5: =IF(V5="Y",S5,"") | X5: sources disagree: map uses the official 50 mph (OSM/imagery: osm 30) | Y5: 1 | Z5: 25
A6: CBD-B1-005 | B6: Carlsbad | C6: Carlsbad Boulevard | D6: Avenida Encinas | E6: Ponto Road | F6: 436431494 | G6: 50 | H6: city/county | I6: no | J6: https://www.google.com/maps/@?api=1&map_action=pano&viewpoint=33.097898,-117.316580&heading=342 | K6: https://www.google.com/maps/search/?api=1&query=33.097898,-117.316580 | P6: pending | S6: 50 | T6: Carlsbad Blvd (Island Way - south city limit (Batiquitos Lagoon to Leucadia)) | U6: https://ecode360.com/44006773 | V6: =IF(OR(L6="",S6=""),"",IF(VALUE(L6)=VALUE(S6),"Y","N")) | W6: =IF(V6="Y",S6,"") | X6: sources disagree: map uses the official 50 mph (OSM/imagery: osm 30) | Y6: 1 | Z6: 87
A7: CBD-B1-006 | B7: Carlsbad | C7: Carlsbad Boulevard | D7: Poinsettia Lane | E7: Ponto Road | F7: 436431492 | G7: 50 | H7: city/county | I7: no | J7: https://www.google.com/maps/@?api=1&map_action=pano&viewpoint=33.098481,-117.316962&heading=166 | K7: https://www.google.com/maps/search/?api=1&query=33.098481,-117.316962 | P7: pending | S7: 50 | T7: Carlsbad Blvd (Island Way - south city limit (Batiquitos Lagoon to Leucadia)) | U7: https://ecode360.com/44006773 | V7: =IF(OR(L7="",S7=""),"",IF(VALUE(L7)=VALUE(S7),"Y","N")) | W7: =IF(V7="Y",S7,"") | X7: one official source; most-used arterial | Y7: 1 | Z7: 86
A8: CBD-B1-007 | B8: Carlsbad | C8: Carlsbad Boulevard | D8: Ponto Road | E8: Poinsettia Lane | F8: 435654183 | G8: 50 | H8: city/county | I8: no | J8: https://www.google.com/maps/@?api=1&map_action=pano&viewpoint=33.100764,-117.317648&heading=341 | K8: https://www.google.com/maps/search/?api=1&query=33.100764,-117.317648 | P8: pending | S8: 50 | T8: Carlsbad Blvd (Island Way - south city limit (Batiquitos Lagoon to Leucadia)) | U8: https://ecode360.com/44006773 | V8: =IF(OR(L8="",S8=""),"",IF(VALUE(L8)=VALUE(S8),"Y","N")) | W8: =IF(V8="Y",S8,"") | X8: sources disagree: map uses the official 50 mph (OSM/imagery: osm 30) | Y8: 1 | Z8: 322
A9: CBD-B1-008 | B9: Carlsbad | C9: Carlsbad Boulevard | D9: Ponto Road | E9: Poinsettia Lane | F9: 436609337 | G9: 50 | H9: city/county | I9: no | J9: https://www.google.com/maps/@?api=1&map_action=pano&viewpoint=33.101239,-117.317854&heading=341 | K9: https://www.google.com/maps/search/?api=1&query=33.101239,-117.317854 | P9: pending | S9: 50 | T9: Carlsbad Blvd (Island Way - south city limit (Batiquitos Lagoon to Leucadia)) | U9: https://ecode360.com/44006773 | V9: =IF(OR(L9="",S9=""),"",IF(VALUE(L9)=VALUE(S9),"Y","N")) | W9: =IF(V9="Y",S9,"") | X9: sources disagree: map uses the official 50 mph (OSM/imagery: osm 30) | Y9: 1 | Z9: 7
A10: CBD-B1-009 | B10: Carlsbad | C10: Carlsbad Boulevard | D10: Ponto Road | E10: Poinsettia Lane | F10: 435654179 | G10: 50 | H10: city/county | I10: no | J10: https://www.google.com/maps/@?api=1&map_action=pano&viewpoint=33.101712,-117.318044&heading=341 | K10: https://www.google.com/maps/search/?api=1&query=33.101712,-117.318044 | P10: pending | S10: 50 | T10: Carlsbad Blvd (Island Way - south city limit (Batiquitos Lagoon to Leucadia)) | U10: https://ecode360.com/44006773 | V10: =IF(OR(L10="",S10=""),"",IF(VALUE(L10)=VALUE(S10),"Y","N")) | W10: =IF(V10="Y",S10,"") | X10: sources disagree: map uses the official 50 mph (OSM/imagery: osm 30) | Y10: 1 | Z10: 63
A11: CBD-B1-010 | B11: Carlsbad | C11: Carlsbad Boulevard | D11: Breakwater Road | E11: Poinsettia Lane | F11: 435654177 | G11: 50 | H11: city/county | I11: no | J11: https://www.google.com/maps/@?api=1&map_action=pano&viewpoint=33.102103,-117.318378&heading=160 | K11: https://www.google.com/maps/search/?api=1&query=33.102103,-117.318378 | P11: pending | S11: 50 | T11: Carlsbad Blvd (Island Way - south city limit (Batiquitos Lagoon to Leucadia)) | U11: https://ecode360.com/44006773 | V11: =IF(OR(L11="",S11=""),"",IF(VALUE(L11)=VALUE(S11),"Y","N")) | W11: =IF(V11="Y",S11,"") | X11: one official source; most-used arterial | Y11: 1 | Z11: 108
A12: CBD-B1-011 | B12: Carlsbad | C12: Carlsbad Boulevard | D12: Poinsettia Lane | E12: Breakwater Road | F12: 435654178 | G12: 50 | H12: city/county | I12: no | J12: https://www.google.com/maps/@?api=1&map_action=pano&viewpoint=33.105886,-117.319926&heading=337 | K12: https://www.google.com/maps/search/?api=1&query=33.105886,-117.319926 | P12: pending | S12: 50 | T12: Carlsbad Blvd (Island Way - south city limit (Batiquitos Lagoon to Leucadia)) | U12: https://ecode360.com/44006773 | V12: =IF(OR(L12="",S12=""),"",IF(VALUE(L12)=VALUE(S12),"Y","N")) | W12: =IF(V12="Y",S12,"") | X12: sources disagree: map uses the official 50 mph (OSM/imagery: osm 30) | Y12: 1 | Z12: 89
A13: CBD-B1-012 | B13: Carlsbad | C13: Carlsbad Boulevard | D13: Island Way | E13: Breakwater Road | F13: 435654180 | G13: 50 | H13: city/county | I13: no | J13: https://www.google.com/maps/@?api=1&map_action=pano&viewpoint=33.106054,-117.320209&heading=154 | K13: https://www.google.com/maps/search/?api=1&query=33.106054,-117.320209 | P13: pending | S13: 50 | T13: Carlsbad Blvd (Island Way - south city limit (Batiquitos Lagoon to Leucadia)) | U13: https://ecode360.com/44006773 | V13: =IF(OR(L13="",S13=""),"",IF(VALUE(L13)=VALUE(S13),"Y","N")) | W13: =IF(V13="Y",S13,"") | X13: one official source; most-used arterial | Y13: 1 | Z13: 70
... A23: CBD-B1-022 | B23: Carlsbad | C23: Carlsbad Boulevard | D23: Sequoia Avenue | E23: Tamarack Avenue | F23: 436429114 | G23: 35 | H23: city/county | I23: LSV | J23: https://www.google.com/maps/@?api=1&map_action=pano&viewpoint=33.141602,-117.340718&heading=154 | K23: https://www.google.com/maps/search/?api=1&query=33.141602,-117.340718 | P23: pending | S23: 35 | T23: Carlsbad Blvd (Tamarack - 1,400 ft S of Manzano Dr) | U23: https://ecode360.com/44006773 | V23: =IF(OR(L23="",S23=""),"",IF(VALUE(L23)=VALUE(S23),"Y","N")) | W23: =IF(V23="Y",S23,"") | X23: one official source; most-used arterial | Y23: 1 | Z23: 397
A24: CBD-B1-023 | B24: Carlsbad | C24: Carlsbad Boulevard | D24: Sequoia Avenue | F24: 157272817 | G24: 35 | H24: city/county | I24: LSV | J24: https://www.google.com/maps/@?api=1&map_action=pano&viewpoint=33.145299,-117.343467&heading=142 | K24: https://www.google.com/maps/search/?api=1&query=33.145299,-117.343467 | P24: pending | S24: 35 | T24: Carlsbad Blvd (Tamarack - 1,400 ft S of Manzano Dr) | U24: https://ecode360.com/44006773 | V24: =IF(OR(L24="",S24=""),"",IF(VALUE(L24)=VALUE(S24),"Y","N")) | W24: =IF(V24="Y",S24,"") | X24: sources disagree: map uses the official 35 mph (OSM/imagery: osm 30) | Y24: 1 | Z24: 77
A25: CBD-B1-024 | B25: Carlsbad | C25: Carlsbad Boulevard | D25: Tamarack Avenue | E25: Sequoia Avenue | F25: 436429085 | G25: 35 | H25: city/county | I25: LSV | J25: https://www.google.com/maps/@?api=1&map_action=pano&viewpoint=33.146853,-117.344830&heading=147 | K25: https://www.google.com/maps/search/?api=1&query=33.146853,-117.344830 | P25: pending | S25: 35 | T25: Carlsbad Blvd (Tamarack - 1,400 ft S of Manzano Dr) | U25: https://ecode360.com/44006773 | V25: =IF(OR(L25="",S25=""),"",IF(VALUE(L25)=VALUE(S25),"Y","N")) | W25: =IF(V25="Y",S25,"") | X25: sources disagree: map uses the official 35 mph (OSM/imagery: osm 30) | Y25: 1 | Z25: 36
A26: CBD-B1-025 | B26: Carlsbad | C26: Carlsbad Boulevard | D26: Tamarack Avenue | E26: Sequoia Avenue | F26: 436429075 | G26: 35 | H26: city/county | I26: LSV | J26: https://www.google.com/maps/@?api=1&map_action=pano&viewpoint=33.147125,-117.345040&heading=146 | K26: https://www.google.com/maps/search/?api=1&query=33.147125,-117.345040 | P26: pending | S26: 35 | T26: Carlsbad Blvd (Tamarack - 1,400 ft S of Manzano Dr) | U26: https://ecode360.com/44006773 | V26: =IF(OR(L26="",S26=""),"",IF(VALUE(L26)=VALUE(S26),"Y","N")) | W26: =IF(V26="Y",S26,"") | X26: sources disagree: map uses the official 35 mph (OSM/imagery: osm 30) | Y26: 1 | Z26: 18
A27: CBD-B1-026 | B27: Carlsbad | C27: Carlsbad Boulevard | D27: Tamarack Avenue | E27: Sequoia Avenue | F27: 157272814 | G27: 35 | H27: city/county | I27: LSV | J27: https://www.google.com/maps/@?api=1&map_action=pano&viewpoint=33.147258,-117.345147&heading=146 | K27: https://www.google.com/maps/search/?api=1&query=33.147258,-117.345147 | P27: pending | S27: 35 | T27: Carlsbad Blvd (Tamarack - 1,400 ft S of Manzano Dr) | U27: https://ecode360.com/44006773 | V27: =IF(OR(L27="",S27=""),"",IF(VALUE(L27)=VALUE(S27),"Y","N")) | W27: =IF(V27="Y",S27,"") | X27: sources disagree: map uses the official 35 mph (OSM/imagery: osm 30) | Y27: 1 | Z27: 35
A28: CBD-B1-027 | B28: Carlsbad | C28: Carlsbad Boulevard | D28: Tamarack Avenue | E28: Redwood Avenue | F28: 436429102 | G28: 35 | H28: city/county | I28: LSV | J28: https://www.google.com/maps/@?api=1&map_action=pano&viewpoint=33.147619,-117.345436&heading=327 | K28: https://www.google.com/maps/search/?api=1&query=33.147619,-117.345436 | P28: pending | S28: 35 | T28: Carlsbad Blvd (Tamarack - 1,400 ft S of Manzano Dr) | U28: https://ecode360.com/44006773 | V28: =IF(OR(L28="",S28=""),"",IF(VALUE(L28)=VALUE(S28),"Y","N")) | W28: =IF(V28="Y",S28,"") | X28: sources disagree: map uses the official 35 mph (OSM/imagery: osm 30) | Y28: 1 | Z28: 36
A29: CBD-B1-028 | B29: Carlsbad | C29: Carlsbad Boulevard | D29: Oak Avenue | E29: Pine Avenue | F29: 436429115 | G29: 30 | H29: city/county | I29: LSV | J29: https://www.google.com/maps/@?api=1&map_action=pano&viewpoint=33.155858,-117.350905&heading=186 | K29: https://www.google.com/maps/search/?api=1&query=33.155858,-117.350905 | P29: pending | S29: 30 | T29: Carlsbad Blvd (State St - Tamarack Ave) | U29: https://ecode360.com/44006773 | V29: =IF(OR(L29="",S29=""),"",IF(VALUE(L29)=VALUE(S29),"Y","N")) | W29: =IF(V29="Y",S29,"") | X29: one official source; most-used arterial | Y29: 1 | Z29: 141
A30: CBD-B1-029 | B30: Carlsbad | C30: Carlsbad Boulevard | D30: Beech Avenue | E30: Christiansen Avenue | F30: 436405051 | G30: 30 | H30: city/county | I30: LSV | J30: https://www.google.com/maps/@?api=1&map_action=pano&viewpoint=33.160241,-117.352725&heading=145 | K30: https://www.google.com/maps/search/?api=1&query=33.160241,-117.352725 | P30: pending | S30: 30 | T30: Carlsbad Blvd (State St - Tamarack Ave) | U30: https://ecode360.com/44006773 | V30: =IF(OR(L30="",S30=""),"",IF(VALUE(L30)=VALUE(S30),"Y","N")) | W30: =IF(V30="Y",S30,"") | X30: sources disagree: map uses the official 30 mph (OSM/imagery: osm 20) | Y30: 1 | Z30: 122
A31: CBD-B1-030 | B31: Carlsbad | C31: Carlsbad Boulevard | D31: Mountain View Drive | E31: Cypress Avenue | F31: 1085300499 | G31: 30 | H31: city/county | I31: LSV | J31: https://www.google.com/maps/@?api=1&map_action=pano&viewpoint=33.162771,-117.354398&heading=171 | K31: https://www.google.com/maps/search/?api=1&query=33.162771,-117.354398 | P31: pending | S31: 30 | T31: Carlsbad Blvd (State St - Tamarack Ave) | U31: https://ecode360.com/44006773 | V31: =IF(OR(L31="",S31=""),"",IF(VALUE(L31)=VALUE(S31),"Y","N")) | W31: =IF(V31="Y",S31,"") | X31: sources disagree: map uses the official 30 mph (OSM/imagery: mapillary 25) | Y31: 1 | Z31: 135
A32: CBD-B1-031 | B32: Carlsbad | C32: Carlsbad Boulevard | D32: South Coast Highway | E32: Mountain View Drive | F32: 526970380 | G32: 30 | H32: city/county | I32: LSV | J32: https://www.google.com/maps/@?api=1&map_action=pano&viewpoint=33.165740,-117.354582&heading=172 | K32: https://www.google.com/maps/search/?api=1&query=33.165740,-117.354582 | P32: pending | S32: 30 | T32: Carlsbad Blvd (State St - Tamarack Ave) | U32: https://ecode360.com/44006773 | V32: =IF(OR(L32="",S32=""),"",IF(VALUE(L32)=VALUE(S32),"Y","N")) | W32: =IF(V32="Y",S32,"") | X32: sources disagree: map uses the official 30 mph (OSM/imagery: osm 15) | Y32: 1 | Z32: 10
A33: CBD-B1-032 | B33: Carlsbad | C33: Carlsbad Boulevard | D33: South Coast Highway | E33: Mountain View Drive | F33: 794576109 | G33: 35 | H33: city/county | I33: LSV | J33: https://www.google.com/maps/@?api=1&map_action=pano&viewpoint=33.165909,-117.354569&heading=167 | K33: https://www.google.com/maps/search/?api=1&query=33.165909,-117.354569 | P33: pending | S33: 35 | T33: Carlsbad Blvd (North city limit - State St) | U33: https://ecode360.com/44006773 | V33: =IF(OR(L33="",S33=""),"",IF(VALUE(L33)=VALUE(S33),"Y","N")) | W33: =IF(V33="Y",S33,"") | X33: sources disagree: map uses the official 35 mph (OSM/imagery: osm 10) | Y33: 1 | Z33: 19
A34: CBD-B1-033 | B34: Carlsbad | C34: Carlsbad Boulevard | D34: South Coast Highway | E34: Mountain View Drive | F34: 382185424 | G34: 35 | H34: city/county | I34: LSV | J34: https://www.google.com/maps/@?api=1&map_action=pano&viewpoint=33.166139,-117.354677&heading=155 | K34: https://www.google.com/maps/search/?api=1&query=33.166139,-117.354677 | P34: pending | S34: 35 | T34: Carlsbad Blvd (North city limit - State St) | U34: https://ecode360.com/44006773 | V34: =IF(OR(L34="",S34=""),"",IF(VALUE(L34)=VALUE(S34),"Y","N")) | W34: =IF(V34="Y",S34,"") | X34: sources disagree: map uses the official 35 mph (OSM/imagery: osm 15) | Y34: 1 | Z34: 46
A35: CBD-B1-034 | B35: Carlsbad | C35: Carlsbad Boulevard | D35: South Coast Highway | E35: Mountain View Drive | F35: 407600254 | G35: 35 | H35: city/county | I35: LSV | J35: https://www.google.com/maps/@?api=1&map_action=pano&viewpoint=33.166569,-117.354912&heading=145 | K35: https://www.google.com/maps/search/?api=1&query=33.166569,-117.354912 | P35: pending | S35: 35 | T35: Carlsbad Blvd (North city limit - State St) | U35: https://ecode360.com/44006773 | V35: =IF(OR(L35="",S35=""),"",IF(VALUE(L35)=VALUE(S35),"Y","N")) | W35: =IF(V35="Y",S35,"") | X35: sources disagree: map uses the official 35 mph (OSM/imagery: osm 25) | Y35: 1 | Z35: 211
A36: CBD-B1-035 | B36: Carlsbad | C36: La Costa Avenue | D36: North Coast Highway | E36: North Vulcan Avenue | F36: 750625054 | G36: 30 | H36: city/county | I36: LSV | J36: https://www.google.com/maps/@?api=1&map_action=pano&viewpoint=33.082615,-117.308638&heading=50 | K36: https://www.google.com/maps/search/?api=1&query=33.082615,-117.308638 | P36: pending | S36: 30 | T36: Encinitas Ord. 2026-05 Exhibit A (2026 E&TS): La Costa Ave (N Coast Hwy 101 - East City Limits) posted 30 | U36: https://ecode360.com/EN5042/laws/LF2740111.pdf | V36: =IF(OR(L36="",S36=""),"",IF(VALUE(L36)=VALUE(S36),"Y","N")) | W36: =IF(V36="Y",S36,"") | X36: sources disagree: map uses the official 30 mph (OSM/imagery: osm 40) | Y36: 1 | Z36: 38
... A81: OCN-B1-002 | B81: Oceanside | C81: South Coast Highway | D81: Morse Street | E81: Pacific Coast Highway | F81: 436403815 | G81: 35 | H81: city/county | I81: LSV | J81: https://www.google.com/maps/@?api=1&map_action=pano&viewpoint=33.178201,-117.364689&heading=145 | K81: https://www.google.com/maps/search/?api=1&query=33.178201,-117.364689 | P81: pending | S81: 35 | T81: Coast Highway (Wisconsin Ave - south city limit) | U81: https://gocodebook.com/library/us/ca/oceanside/oceanside-traffic-code-1/article-xiv-special-speed-zones | V81: =IF(OR(L81="",S81=""),"",IF(VALUE(L81)=VALUE(S81),"Y","N")) | W81: =IF(V81="Y",S81,"") | X81: sources disagree: map uses the official 35 mph (OSM/imagery: osm 30) | Y81: 1 | Z81: 23
A82: OCN-B1-003 | B82: Oceanside | C82: Wisconsin Avenue | D82: South Pacific Street | F82: 5967620 | G82: 25 | H82: city/county | I82: cart+LSV | J82: https://www.google.com/maps/@?api=1&map_action=pano&viewpoint=33.186576,-117.376277&heading=55 | K82: https://www.google.com/maps/search/?api=1&query=33.186576,-117.376277 | P82: pending | S82: 25 | T82: Oceanside Traffic Code Art. XIV 18: Wisconsin Avenue (South Coast Highway - South Pacific Street) posted 25 | U82: https://gocodebook.com/library/us/ca/oceanside/oceanside-traffic-code-1/article-xiv-special-speed-zones | V82: =IF(OR(L82="",S82=""),"",IF(VALUE(L82)=VALUE(S82),"Y","N")) | W82: =IF(V82="Y",S82,"") | X82: one official source; most-used arterial | Y82: 2 | Z82: 106
A83: OCN-B1-004 | B83: Oceanside | C83: Wisconsin Avenue | D83: South Myers Street | E83: South Tait Street | F83: 617084571 | G83: 25 | H83: city/county | I83: cart+LSV | J83: https://www.google.com/maps/@?api=1&map_action=pano&viewpoint=33.187265,-117.375345&heading=37 | K83: https://www.google.com/maps/search/?api=1&query=33.187265,-117.375345 | P83: pending | S83: 25 | T83: Oceanside Traffic Code Art. XIV 18: Wisconsin Avenue (South Coast Highway - South Pacific Street) posted 25 | U83: https://gocodebook.com/library/us/ca/oceanside/oceanside-traffic-code-1/article-xiv-special-speed-zones | V83: =IF(OR(L83="",S83=""),"",IF(VALUE(L83)=VALUE(S83),"Y","N")) | W83: =IF(V83="Y",S83,"") | X83: one official source; most-used arterial | Y83: 2 | Z83: 113
A84: OCN-B1-005 | B84: Oceanside | C84: Wisconsin Avenue | D84: South Myers Street | E84: Pacific Coast Highway | F84: 617084573 | G84: 25 | H84: city/county | I84: cart+LSV | J84: https://www.google.com/maps/@?api=1&map_action=pano&viewpoint=33.188260,-117.373842&heading=54 | K84: https://www.google.com/maps/search/?api=1&query=33.188260,-117.373842 | P84: pending | S84: 25 | T84: Oceanside Traffic Code Art. XIV 18: Wisconsin Avenue (South Coast Highway - South Pacific Street) posted 25 | U84: https://gocodebook.com/library/us/ca/oceanside/oceanside-traffic-code-1/article-xiv-special-speed-zones | V84: =IF(OR(L84="",S84=""),"",IF(VALUE(L84)=VALUE(S84),"Y","N")) | W84: =IF(V84="Y",S84,"") | X84: one official source; most-used arterial | Y84: 2 | Z84: 183
A85: PBC-B1-001 | B85: Pacific Beach / Mission Beach | C85: La Jolla Boulevard | D85: Opal Street | E85: Loring Street | F85: 436401815 | G85: 25 | H85: city/county | I85: cart+LSV | J85: https://www.google.com/maps/@?api=1&map_action=pano&viewpoint=32.804989,-117.258585&heading=148 | K85: https://www.google.com/maps/search/?api=1&query=32.804989,-117.258585 | P85: pending | S85: 25 | T85: San Diego R-316675 Table 7, posted: La Jolla Bl (Loring St - Colima St) | U85: https://docs.sandiego.gov/council_reso_ordinance/rao2026/R-316675.pdf | V85: =IF(OR(L85="",S85=""),"",IF(VALUE(L85)=VALUE(S85),"Y","N")) | W85: =IF(V85="Y",S85,"") | X85: sources disagree: map uses the official 25 mph (OSM/imagery: mapillary 35) | Y85: 1 | Z85: 31
A86: PBC-B1-002 | B86: Pacific Beach / Mission Beach | C86: Mission Boulevard | D86: Ventura Place | E86: San Fernando Place | F86: 436400933 | G86: 25 | H86: city/county | I86: cart+LSV | J86: https://www.google.com/maps/@?api=1&map_action=pano&viewpoint=32.769886,-117.251031&heading=178 | K86: https://www.google.com/maps/search/?api=1&query=32.769886,-117.251031 | P86: pending | S86: 25 | T86: San Diego R-316675 Table 7, posted: Mission Bl (San Fernando Pl - Santa Clara Pl) | U86: https://docs.sandiego.gov/council_reso_ordinance/rao2026/R-316675.pdf | V86: =IF(OR(L86="",S86=""),"",IF(VALUE(L86)=VALUE(S86),"Y","N")) | W86: =IF(V86="Y",S86,"") | X86: one official source; most-used arterial | Y86: 1 | Z86: 70
A87: PBC-B1-003 | B87: Pacific Beach / Mission Beach | C87: Mission Boulevard | D87: San Fernando Place | E87: West Mission Bay Drive | F87: 436400936 | G87: 25 | H87: city/county | I87: cart+LSV | J87: https://www.google.com/maps/@?api=1&map_action=pano&viewpoint=32.770753,-117.250884&heading=355 | K87: https://www.google.com/maps/search/?api=1&query=32.770753,-117.250884 | P87: pending | S87: 25 | T87: San Diego R-316675 Table 7, posted: Mission Bl (San Fernando Pl - Santa Clara Pl) | U87: https://docs.sandiego.gov/council_reso_ordinance/rao2026/R-316675.pdf | V87: =IF(OR(L87="",S87=""),"",IF(VALUE(L87)=VALUE(S87),"Y","N")) | W87: =IF(V87="Y",S87,"") | X87: one official source; most-used arterial | Y87: 1 | Z87: 135
A88: PBC-B1-004 | B88: Pacific Beach / Mission Beach | C88: Mission Boulevard | D88: Ventura Place | E88: San Fernando Place | F88: 436400938 | G88: 25 | H88: city/county | I88: cart+LSV | J88: https://www.google.com/maps/@?api=1&map_action=pano&viewpoint=32.771256,-117.251118&heading=172 | K88: https://www.google.com/maps/search/?api=1&query=32.771256,-117.251118 | P88: pending | S88: 25 | T88: San Diego R-316675 Table 7, posted: Mission Bl (San Fernando Pl - Santa Clara Pl) | U88: https://docs.sandiego.gov/council_reso_ordinance/rao2026/R-316675.pdf | V88: =IF(OR(L88="",S88=""),"",IF(VALUE(L88)=VALUE(S88),"Y","N")) | W88: =IF(V88="Y",S88,"") | X88: sources disagree: map uses the official 25 mph (OSM/imagery: mapillary 30) | Y88: 1 | Z88: 149
A89: PBC-B1-005 | B89: Pacific Beach / Mission Beach | C89: Mission Boulevard | D89: San Fernando Place | E89: West Mission Bay Drive | F89: 436400932 | G89: 25 | H89: city/county | I89: cart+LSV | J89: https://www.google.com/maps/@?api=1&map_action=pano&viewpoint=32.771870,-117.251098&heading=351 | K89: https://www.google.com/maps/search/?api=1&query=32.771870,-117.251098 | P89: pending | S89: 25 | T89: San Diego R-316675 Table 7, posted: Mission Bl (San Fernando Pl - Santa Clara Pl) | U89: https://docs.sandiego.gov/council_reso_ordinance/rao2026/R-316675.pdf | V89: =IF(OR(L89="",S89=""),"",IF(VALUE(L89)=VALUE(S89),"Y","N")) | W89: =IF(V89="Y",S89,"") | X89: one official source; most-used arterial | Y89: 1 | Z89: 74
A90: PBC-B1-006 | B90: Pacific Beach / Mission Beach | C90: Mission Boulevard | D90: West Mission Bay Drive | E90: Santa Barbara Place | F90: 1019974701 | G90: 25 | H90: city/county | I90: cart+LSV | J90: https://www.google.com/maps/@?api=1&map_action=pano&viewpoint=32.773130,-117.251355&heading=350 | K90: https://www.google.com/maps/search/?api=1&query=32.773130,-117.251355 | P90: pending | S90: 25 | T90: San Diego R-316675 Table 7, posted: Mission Bl (San Fernando Pl - Santa Clara Pl) | U90: https://docs.sandiego.gov/council_reso_ordinance/rao2026/R-316675.pdf | V90: =IF(OR(L90="",S90=""),"",IF(VALUE(L90)=VALUE(S90),"Y","N")) | W90: =IF(V90="Y",S90,"") | X90: sources disagree: map uses the official 25 mph (OSM/imagery: mapillary 30) | Y90: 1 | Z90: 184
A91: PBC-B1-007 | B91: Pacific Beach / Mission Beach | C91: Mission Boulevard | D91: Santa Barbara Place | E91: Ventura Place | F91: 436400724 | G91: 25 | H91: city/county | I91: cart+LSV | J91: https://www.google.com/maps/@?api=1&map_action=pano&viewpoint=32.773380,-117.251493&heading=168 | K91: https://www.google.com/maps/search/?api=1&query=32.773380,-117.251493 | P91: pending | S91: 25 | T91: San Diego R-316675 Table 7, posted: Mission Bl (San Fernando Pl - Santa Clara Pl) | U91: https://docs.sandiego.gov/council_reso_ordinance/rao2026/R-316675.pdf | V91: =IF(OR(L91="",S91=""),"",IF(VALUE(L91)=VALUE(S91),"Y","N")) | W91: =IF(V91="Y",S91,"") | X91: one official source; most-used arterial | Y91: 1 | Z91: 163
A92: PBC-B1-008 | B92: Pacific Beach / Mission Beach | C92: Mission Boulevard | D92: San Luis Obispo Place | E92: Santa Barbara Place | F92: 436400725 | G92: 25 | H92: city/county | I92: cart+LSV | J92: https://www.google.com/maps/@?api=1&map_action=pano&viewpoint=32.775441,-117.252172&heading=164 | K92: https://www.google.com/maps/search/?api=1&query=32.775441,-117.252172 | P92: pending | S92: 25 | T92: San Diego R-316675 Table 7, posted: Mission Bl (San Fernando Pl - Santa Clara Pl) | U92: https://docs.sandiego.gov/council_reso_ordinance/rao2026/R-316675.pdf | V92: =IF(OR(L92="",S92=""),"",IF(VALUE(L92)=VALUE(S92),"Y","N")) | W92: =IF(V92="Y",S92,"") | X92: one official source; most-used arterial | Y92: 1 | Z92: 168
A93: PBC-B1-009 | B93: Pacific Beach / Mission Beach | C93: Mission Boulevard | D93: San Luis Obispo Place | E93: Tom Lane | F93: 1025161103 | G93: 25 | H93: city/county | I93: cart+LSV | J93: https://www.google.com/maps/@?api=1&map_action=pano&viewpoint=32.777001,-117.252478&heading=351 | K93: https://www.google.com/maps/search/?api=1&query=32.777001,-117.252478 | P93: pending | S93: 25 | T93: San Diego R-316675 Table 7, posted: Mission Bl (San Fernando Pl - Santa Clara Pl) | U93: https://docs.sandiego.gov/council_reso_ordinance/rao2026/R-316675.pdf | V93: =IF(OR(L93="",S93=""),"",IF(VALUE(L93)=VALUE(S93),"Y","N")) | W93: =IF(V93="Y",S93,"") | X93: one official source; most-used arterial | Y93: 1 | Z93: 199
...

Sheet How to check
A1: Street View batch 1: the 70 roads where our sources disagree, plus the 30 busiest main roads that have only a city source. Your reading is the deciding second source.
A2: Fill only the blue columns (posted_speed_seen_mph … notes). The yellow columns are ours: our_gis_survey_mph is what the city code/survey says; agree_YN and resolved_mph fill themselves.
A4: # Golf Cart Map — Street View speed-limit checker guide
A6: Purpose: confirm the POSTED speed limit on each road in the sheet using Google Maps Street View. The answer decides whether the road is legal for golf carts (posted 25 mph or less) and LSVs (posted 35 mph or less). A wrong number can send someone onto an illegal road, so record only what you actually see on a sign. Never guess.
A8: Time budget: about 2-3 minutes per road. If a road takes more than 5 minutes, stop, set status to "can't tell", write what you saw in notes, and move on.
A10: ## Before you start
A11: 1. Use a computer (laptop/desktop) with Chrome, Firefox, Safari or Edge. A phone works but is much slower.
A12: 2. Open the Google Sheet. Go to the "Roads" tab.
A13: 3. Find the first row where status = "pending" and checker_initials is empty. Type your initials in checker_initials right away so nobody else picks the same row.
A14: 4. Each row is one road segment: road_name, between from_cross_street and to_cross_street, in the given city. "(nearby)" means the cross street is near but not touching that end; "(next block)" means both ends meet the same street; "(see map)" means use map_link to see where it is.
A16: ## Step-by-step for each row
A17: 1. Click the street_view_link in that row. It opens Google Maps in Street View at a point in the middle of the segment, facing along the road.
... A65: - For two-source agreement (the plan requires two agreeing sources before a popular-route segment shows as verified), the sheet gets second_checker_initials and second_posted_speed_mph columns. A different person re-checks a row without looking at the first answer; the row is verified only when both match. The Summary tab tracks done, mismatches against our map, and percent complete.

Sheet Summary
A1: metric | B1: value
A2: total roads | B2: =COUNTA(Roads!A2:A101)
A3: done | B3: =COUNTIF(Roads!P2:P101,"done")
A4: can't tell | B4: =COUNTIF(Roads!P2:P101,"can't tell")
A5: pending | B5: =COUNTIF(Roads!P2:P101,"pending")
A6: percent done | B6: =IF(B2=0,0,(B3+B4)/B2)
A7: compared (sign read and we have a GIS/survey value) | B7: =COUNTIF(Roads!V2:V101,"Y")+COUNTIF(Roads!V2:V101,"N")
A8: agreed (Y) | B8: =COUNTIF(Roads!V2:V101,"Y")
A9: disagreed (N) | B9: =COUNTIF(Roads!V2:V101,"N")
A10: % agreed | B10: =IF(B7=0,"",B8/B7)
A11: mismatched vs our map (done rows) | B11: =SUMPRODUCT((Roads!P2:P101="done")*(Roads!L2:L101<>"")*(Roads!L2:L101<>Roads!G2:G101))
